[2025-04-17T12:20:14.777+0000] {local_task_job_runner.py:123} INFO - ::group::Pre task execution logs
[2025-04-17T12:20:14.791+0000] {taskinstance.py:2612} INFO - Dependencies all met for dep_context=non-requeueable deps ti=<TaskInstance: medium_to_pinecone.create_pinecone_index manual__2025-04-17T12:19:21.900846+00:00 [queued]>
[2025-04-17T12:20:14.801+0000] {taskinstance.py:2612} INFO - Dependencies all met for dep_context=requeueable deps ti=<TaskInstance: medium_to_pinecone.create_pinecone_index manual__2025-04-17T12:19:21.900846+00:00 [queued]>
[2025-04-17T12:20:14.802+0000] {taskinstance.py:2865} INFO - Starting attempt 1 of 2
[2025-04-17T12:20:14.817+0000] {taskinstance.py:2888} INFO - Executing <Task(PythonOperator): create_pinecone_index> on 2025-04-17 12:19:21.900846+00:00
[2025-04-17T12:20:14.830+0000] {standard_task_runner.py:104} INFO - Running: ['***', 'tasks', 'run', 'medium_to_pinecone', 'create_pinecone_index', 'manual__2025-04-17T12:19:21.900846+00:00', '--job-id', '107', '--raw', '--subdir', 'DAGS_FOLDER/medium_to_pinecone_dag.py', '--cfg-path', '/tmp/tmp5jrfiv2x']
[2025-04-17T12:20:14.832+0000] {standard_task_runner.py:105} INFO - Job 107: Subtask create_pinecone_index
[2025-04-17T12:20:14.835+0000] {logging_mixin.py:190} WARNING - /home/***/.local/lib/python3.12/site-packages/***/task/task_runner/standard_task_runner.py:70 DeprecationWarning: This process (pid=2860) is multi-threaded, use of fork() may lead to deadlocks in the child.
[2025-04-17T12:20:14.836+0000] {standard_task_runner.py:72} INFO - Started process 2898 to run task
[2025-04-17T12:20:14.865+0000] {task_command.py:467} INFO - Running <TaskInstance: medium_to_pinecone.create_pinecone_index manual__2025-04-17T12:19:21.900846+00:00 [running]> on host c4a090d2ac67
[2025-04-17T12:20:14.921+0000] {taskinstance.py:3131} INFO - Exporting env vars: AIRFLOW_CTX_DAG_OWNER='***' AIRFLOW_CTX_DAG_ID='medium_to_pinecone' AIRFLOW_CTX_TASK_ID='create_pinecone_index' AIRFLOW_CTX_EXECUTION_DATE='2025-04-17T12:19:21.900846+00:00' AIRFLOW_CTX_TRY_NUMBER='1' AIRFLOW_CTX_DAG_RUN_ID='manual__2025-04-17T12:19:21.900846+00:00'
[2025-04-17T12:20:14.922+0000] {taskinstance.py:731} INFO - ::endgroup::
[2025-04-17T12:20:17.315+0000] {taskinstance.py:3310} ERROR - Task failed with exception
Traceback (most recent call last):
  File "/home/airflow/.local/lib/python3.12/site-packages/airflow/models/taskinstance.py", line 767, in _execute_task
    result = _execute_callable(context=context, **execute_callable_kwargs)
             ^^^^^^^^^^^^^^^^^^^^^^^^^^^^^^^^^^^^^^^^^^^^^^^^^^^^^^^^^^^^^
  File "/home/airflow/.local/lib/python3.12/site-packages/airflow/models/taskinstance.py", line 733, in _execute_callable
    return ExecutionCallableRunner(
           ^^^^^^^^^^^^^^^^^^^^^^^^
  File "/home/airflow/.local/lib/python3.12/site-packages/airflow/utils/operator_helpers.py", line 252, in run
    return self.func(*args, **kwargs)
           ^^^^^^^^^^^^^^^^^^^^^^^^^^
  File "/home/airflow/.local/lib/python3.12/site-packages/airflow/models/baseoperator.py", line 406, in wrapper
    return func(self, *args, **kwargs)
           ^^^^^^^^^^^^^^^^^^^^^^^^^^^
  File "/home/airflow/.local/lib/python3.12/site-packages/airflow/operators/python.py", line 238, in execute
    return_value = self.execute_callable()
                   ^^^^^^^^^^^^^^^^^^^^^^^
  File "/home/airflow/.local/lib/python3.12/site-packages/airflow/operators/python.py", line 256, in execute_callable
    return runner.run(*self.op_args, **self.op_kwargs)
           ^^^^^^^^^^^^^^^^^^^^^^^^^^^^^^^^^^^^^^^^^^^
  File "/home/airflow/.local/lib/python3.12/site-packages/airflow/utils/operator_helpers.py", line 252, in run
    return self.func(*args, **kwargs)
           ^^^^^^^^^^^^^^^^^^^^^^^^^^
  File "/opt/airflow/dags/medium_to_pinecone_dag.py", line 44, in setup_pinecone_index
    pc.create_index(
  File "/home/airflow/.local/lib/python3.12/site-packages/pinecone/control/pinecone.py", line 180, in create_index
    api_instance.create_index(create_index_request=CreateIndexRequest(name=name, dimension=dimension, metric=metric, spec=spec.asdict()))
  File "/home/airflow/.local/lib/python3.12/site-packages/pinecone/core/client/api_client.py", line 771, in __call__
    return self.callable(self, *args, **kwargs)
           ^^^^^^^^^^^^^^^^^^^^^^^^^^^^^^^^^^^^
  File "/home/airflow/.local/lib/python3.12/site-packages/pinecone/core/client/api/manage_indexes_api.py", line 370, in __create_index
    return self.call_with_http_info(**kwargs)
           ^^^^^^^^^^^^^^^^^^^^^^^^^^^^^^^^^^
  File "/home/airflow/.local/lib/python3.12/site-packages/pinecone/core/client/api_client.py", line 833, in call_with_http_info
    return self.api_client.call_api(
           ^^^^^^^^^^^^^^^^^^^^^^^^^
  File "/home/airflow/.local/lib/python3.12/site-packages/pinecone/core/client/api_client.py", line 408, in call_api
    return self.__call_api(resource_path, method,
           ^^^^^^^^^^^^^^^^^^^^^^^^^^^^^^^^^^^^^^
  File "/home/airflow/.local/lib/python3.12/site-packages/pinecone/core/client/api_client.py", line 202, in __call_api
    raise e
  File "/home/airflow/.local/lib/python3.12/site-packages/pinecone/core/client/api_client.py", line 195, in __call_api
    response_data = self.request(
                    ^^^^^^^^^^^^^
  File "/home/airflow/.local/lib/python3.12/site-packages/pinecone/core/client/api_client.py", line 454, in request
    return self.rest_client.POST(url,
           ^^^^^^^^^^^^^^^^^^^^^^^^^^
  File "/home/airflow/.local/lib/python3.12/site-packages/pinecone/core/client/rest.py", line 301, in POST
    return self.request("POST", url,
           ^^^^^^^^^^^^^^^^^^^^^^^^^
  File "/home/airflow/.local/lib/python3.12/site-packages/pinecone/core/client/rest.py", line 260, in request
    raise PineconeApiException(http_resp=r)
pinecone.core.client.exceptions.PineconeApiException: (400)
Reason: Bad Request
HTTP response headers: HTTPHeaderDict({'content-type': 'text/plain; charset=utf-8', 'access-control-allow-origin': '*', 'vary': 'origin,access-control-request-method,access-control-request-headers', 'access-control-expose-headers': '*', 'x-pinecone-api-version': '2024-04', 'x-cloud-trace-context': 'be01af086c9f53968197e79faf6295bb', 'date': 'Thu, 17 Apr 2025 12:20:17 GMT', 'server': 'Google Frontend', 'Content-Length': '202', 'Via': '1.1 google', 'Alt-Svc': 'h3=":443"; ma=2592000,h3-29=":443"; ma=2592000'})
HTTP response body: {"error":{"code":"INVALID_ARGUMENT","message":"Bad request: Your free plan does not support indexes in the us-central1 region of gcp. To create indexes in this region, upgrade your plan."},"status":400}

[2025-04-17T12:20:17.343+0000] {taskinstance.py:1225} INFO - Marking task as UP_FOR_RETRY. dag_id=medium_to_pinecone, task_id=create_pinecone_index, run_id=manual__2025-04-17T12:19:21.900846+00:00, execution_date=20250417T121921, start_date=20250417T122014, end_date=20250417T122017
[2025-04-17T12:20:17.376+0000] {taskinstance.py:340} INFO - ::group::Post task execution logs
[2025-04-17T12:20:17.377+0000] {standard_task_runner.py:124} ERROR - Failed to execute job 107 for task create_pinecone_index ((400)
Reason: Bad Request
HTTP response headers: HTTPHeaderDict({'content-type': 'text/plain; charset=utf-8', 'access-control-allow-origin': '*', 'vary': 'origin,access-control-request-method,access-control-request-headers', 'access-control-expose-headers': '*', 'x-pinecone-api-version': '2024-04', 'x-cloud-trace-context': 'be01af086c9f53968197e79faf6295bb', 'date': 'Thu, 17 Apr 2025 12:20:17 GMT', 'server': 'Google Frontend', 'Content-Length': '202', 'Via': '1.1 google', 'Alt-Svc': 'h3=":443"; ma=2592000,h3-29=":443"; ma=2592000'})
HTTP response body: {"error":{"code":"INVALID_ARGUMENT","message":"Bad request: Your free plan does not support indexes in the us-central1 region of gcp. To create indexes in this region, upgrade your plan."},"status":400}
; 2898)
Traceback (most recent call last):
  File "/home/airflow/.local/lib/python3.12/site-packages/airflow/task/task_runner/standard_task_runner.py", line 117, in _start_by_fork
    ret = args.func(args, dag=self.dag)
          ^^^^^^^^^^^^^^^^^^^^^^^^^^^^^
  File "/home/airflow/.local/lib/python3.12/site-packages/airflow/cli/cli_config.py", line 49, in command
    return func(*args, **kwargs)
           ^^^^^^^^^^^^^^^^^^^^^
  File "/home/airflow/.local/lib/python3.12/site-packages/airflow/utils/cli.py", line 115, in wrapper
    return f(*args, **kwargs)
           ^^^^^^^^^^^^^^^^^^
  File "/home/airflow/.local/lib/python3.12/site-packages/airflow/cli/commands/task_command.py", line 483, in task_run
    task_return_code = _run_task_by_selected_method(args, _dag, ti)
                       ^^^^^^^^^^^^^^^^^^^^^^^^^^^^^^^^^^^^^^^^^^^^
  File "/home/airflow/.local/lib/python3.12/site-packages/airflow/cli/commands/task_command.py", line 256, in _run_task_by_selected_method
    return _run_raw_task(args, ti)
           ^^^^^^^^^^^^^^^^^^^^^^^
  File "/home/airflow/.local/lib/python3.12/site-packages/airflow/cli/commands/task_command.py", line 341, in _run_raw_task
    return ti._run_raw_task(
           ^^^^^^^^^^^^^^^^^
  File "/home/airflow/.local/lib/python3.12/site-packages/airflow/utils/session.py", line 97, in wrapper
    return func(*args, session=session, **kwargs)
           ^^^^^^^^^^^^^^^^^^^^^^^^^^^^^^^^^^^^^^
  File "/home/airflow/.local/lib/python3.12/site-packages/airflow/models/taskinstance.py", line 3004, in _run_raw_task
    return _run_raw_task(
           ^^^^^^^^^^^^^^
  File "/home/airflow/.local/lib/python3.12/site-packages/airflow/models/taskinstance.py", line 273, in _run_raw_task
    TaskInstance._execute_task_with_callbacks(
  File "/home/airflow/.local/lib/python3.12/site-packages/airflow/models/taskinstance.py", line 3158, in _execute_task_with_callbacks
    result = self._execute_task(context, task_orig)
             ^^^^^^^^^^^^^^^^^^^^^^^^^^^^^^^^^^^^^^
  File "/home/airflow/.local/lib/python3.12/site-packages/airflow/models/taskinstance.py", line 3182, in _execute_task
    return _execute_task(self, context, task_orig)
           ^^^^^^^^^^^^^^^^^^^^^^^^^^^^^^^^^^^^^^^
  File "/home/airflow/.local/lib/python3.12/site-packages/airflow/models/taskinstance.py", line 767, in _execute_task
    result = _execute_callable(context=context, **execute_callable_kwargs)
             ^^^^^^^^^^^^^^^^^^^^^^^^^^^^^^^^^^^^^^^^^^^^^^^^^^^^^^^^^^^^^
  File "/home/airflow/.local/lib/python3.12/site-packages/airflow/models/taskinstance.py", line 733, in _execute_callable
    return ExecutionCallableRunner(
           ^^^^^^^^^^^^^^^^^^^^^^^^
  File "/home/airflow/.local/lib/python3.12/site-packages/airflow/utils/operator_helpers.py", line 252, in run
    return self.func(*args, **kwargs)
           ^^^^^^^^^^^^^^^^^^^^^^^^^^
  File "/home/airflow/.local/lib/python3.12/site-packages/airflow/models/baseoperator.py", line 406, in wrapper
    return func(self, *args, **kwargs)
           ^^^^^^^^^^^^^^^^^^^^^^^^^^^
  File "/home/airflow/.local/lib/python3.12/site-packages/airflow/operators/python.py", line 238, in execute
    return_value = self.execute_callable()
                   ^^^^^^^^^^^^^^^^^^^^^^^
  File "/home/airflow/.local/lib/python3.12/site-packages/airflow/operators/python.py", line 256, in execute_callable
    return runner.run(*self.op_args, **self.op_kwargs)
           ^^^^^^^^^^^^^^^^^^^^^^^^^^^^^^^^^^^^^^^^^^^
  File "/home/airflow/.local/lib/python3.12/site-packages/airflow/utils/operator_helpers.py", line 252, in run
    return self.func(*args, **kwargs)
           ^^^^^^^^^^^^^^^^^^^^^^^^^^
  File "/opt/airflow/dags/medium_to_pinecone_dag.py", line 44, in setup_pinecone_index
    pc.create_index(
  File "/home/airflow/.local/lib/python3.12/site-packages/pinecone/control/pinecone.py", line 180, in create_index
    api_instance.create_index(create_index_request=CreateIndexRequest(name=name, dimension=dimension, metric=metric, spec=spec.asdict()))
  File "/home/airflow/.local/lib/python3.12/site-packages/pinecone/core/client/api_client.py", line 771, in __call__
    return self.callable(self, *args, **kwargs)
           ^^^^^^^^^^^^^^^^^^^^^^^^^^^^^^^^^^^^
  File "/home/airflow/.local/lib/python3.12/site-packages/pinecone/core/client/api/manage_indexes_api.py", line 370, in __create_index
    return self.call_with_http_info(**kwargs)
           ^^^^^^^^^^^^^^^^^^^^^^^^^^^^^^^^^^
  File "/home/airflow/.local/lib/python3.12/site-packages/pinecone/core/client/api_client.py", line 833, in call_with_http_info
    return self.api_client.call_api(
           ^^^^^^^^^^^^^^^^^^^^^^^^^
  File "/home/airflow/.local/lib/python3.12/site-packages/pinecone/core/client/api_client.py", line 408, in call_api
    return self.__call_api(resource_path, method,
           ^^^^^^^^^^^^^^^^^^^^^^^^^^^^^^^^^^^^^^
  File "/home/airflow/.local/lib/python3.12/site-packages/pinecone/core/client/api_client.py", line 202, in __call_api
    raise e
  File "/home/airflow/.local/lib/python3.12/site-packages/pinecone/core/client/api_client.py", line 195, in __call_api
    response_data = self.request(
                    ^^^^^^^^^^^^^
  File "/home/airflow/.local/lib/python3.12/site-packages/pinecone/core/client/api_client.py", line 454, in request
    return self.rest_client.POST(url,
           ^^^^^^^^^^^^^^^^^^^^^^^^^^
  File "/home/airflow/.local/lib/python3.12/site-packages/pinecone/core/client/rest.py", line 301, in POST
    return self.request("POST", url,
           ^^^^^^^^^^^^^^^^^^^^^^^^^
  File "/home/airflow/.local/lib/python3.12/site-packages/pinecone/core/client/rest.py", line 260, in request
    raise PineconeApiException(http_resp=r)
pinecone.core.client.exceptions.PineconeApiException: (400)
Reason: Bad Request
HTTP response headers: HTTPHeaderDict({'content-type': 'text/plain; charset=utf-8', 'access-control-allow-origin': '*', 'vary': 'origin,access-control-request-method,access-control-request-headers', 'access-control-expose-headers': '*', 'x-pinecone-api-version': '2024-04', 'x-cloud-trace-context': 'be01af086c9f53968197e79faf6295bb', 'date': 'Thu, 17 Apr 2025 12:20:17 GMT', 'server': 'Google Frontend', 'Content-Length': '202', 'Via': '1.1 google', 'Alt-Svc': 'h3=":443"; ma=2592000,h3-29=":443"; ma=2592000'})
HTTP response body: {"error":{"code":"INVALID_ARGUMENT","message":"Bad request: Your free plan does not support indexes in the us-central1 region of gcp. To create indexes in this region, upgrade your plan."},"status":400}

[2025-04-17T12:20:17.433+0000] {local_task_job_runner.py:266} INFO - Task exited with return code 1
[2025-04-17T12:20:17.462+0000] {taskinstance.py:3900} INFO - 0 downstream tasks scheduled from follow-on schedule check
[2025-04-17T12:20:17.466+0000] {local_task_job_runner.py:245} INFO - ::endgroup::
