[2025-03-27T19:54:25.351+0000] {local_task_job_runner.py:123} INFO - ::group::Pre task execution logs
[2025-03-27T19:54:25.364+0000] {taskinstance.py:2612} INFO - Dependencies all met for dep_context=non-requeueable deps ti=<TaskInstance: etl_snowflake.load_raw_data manual__2025-03-27T19:54:23.865818+00:00 [queued]>
[2025-03-27T19:54:25.376+0000] {taskinstance.py:2612} INFO - Dependencies all met for dep_context=requeueable deps ti=<TaskInstance: etl_snowflake.load_raw_data manual__2025-03-27T19:54:23.865818+00:00 [queued]>
[2025-03-27T19:54:25.377+0000] {taskinstance.py:2865} INFO - Starting attempt 1 of 1
[2025-03-27T19:54:25.388+0000] {taskinstance.py:2888} INFO - Executing <Task(_PythonDecoratedOperator): load_raw_data> on 2025-03-27 19:54:23.865818+00:00
[2025-03-27T19:54:25.396+0000] {logging_mixin.py:190} WARNING - /home/***/.local/lib/python3.12/site-packages/***/task/task_runner/standard_task_runner.py:70 DeprecationWarning: This process (pid=655) is multi-threaded, use of fork() may lead to deadlocks in the child.
[2025-03-27T19:54:25.397+0000] {standard_task_runner.py:72} INFO - Started process 658 to run task
[2025-03-27T19:54:25.396+0000] {standard_task_runner.py:104} INFO - Running: ['***', 'tasks', 'run', 'etl_snowflake', 'load_raw_data', 'manual__2025-03-27T19:54:23.865818+00:00', '--job-id', '78', '--raw', '--subdir', 'DAGS_FOLDER/import_dag_hw_6.py', '--cfg-path', '/tmp/tmpfvlvwq5e']
[2025-03-27T19:54:25.398+0000] {standard_task_runner.py:105} INFO - Job 78: Subtask load_raw_data
[2025-03-27T19:54:25.438+0000] {task_command.py:467} INFO - Running <TaskInstance: etl_snowflake.load_raw_data manual__2025-03-27T19:54:23.865818+00:00 [running]> on host edfa4618dc0c
[2025-03-27T19:54:25.518+0000] {taskinstance.py:3131} INFO - Exporting env vars: AIRFLOW_CTX_DAG_OWNER='***' AIRFLOW_CTX_DAG_ID='etl_snowflake' AIRFLOW_CTX_TASK_ID='load_raw_data' AIRFLOW_CTX_EXECUTION_DATE='2025-03-27T19:54:23.865818+00:00' AIRFLOW_CTX_TRY_NUMBER='1' AIRFLOW_CTX_DAG_RUN_ID='manual__2025-03-27T19:54:23.865818+00:00'
[2025-03-27T19:54:25.520+0000] {taskinstance.py:731} INFO - ::endgroup::
[2025-03-27T19:54:25.535+0000] {base.py:84} INFO - Retrieving connection 'snowflake_conn1'
[2025-03-27T19:54:25.536+0000] {connection.py:413} INFO - Snowflake Connector for Python Version: 3.12.1, Python Version: 3.12.5, Platform: Linux-5.15.167.4-microsoft-standard-WSL2-x86_64-with-glibc2.36
[2025-03-27T19:54:25.537+0000] {connection.py:1196} INFO - Connecting to GLOBAL Snowflake domain
[2025-03-27T19:54:25.540+0000] {connection.py:1277} INFO - This connection is in OCSP Fail Open Mode. TLS Certificates would be checked for validity and revocation status. Any other Certificate Revocation related exceptions or OCSP Responder failures would be disregarded in favor of connectivity.
[2025-03-27T19:54:25.926+0000] {import_dag_hw_6.py:23} INFO - 
            CREATE OR REPLACE STAGE raw.blob_stage
            url = 's3://s3-geospatial/readonly/'
            file_format = (type = csv, skip_header = 1, field_optionally_enclosed_by = '"');
        
[2025-03-27T19:54:26.409+0000] {cursor.py:1156} INFO - Number of results in first chunk: 1
[2025-03-27T19:54:26.411+0000] {import_dag_hw_6.py:27} INFO - COPY INTO raw.user_session_channel FROM @raw.blob_stage/user_session_channel.csv;
[2025-03-27T19:54:26.505+0000] {import_dag_hw_6.py:35} ERROR - ETL Process failed: 001757 (42601): 01bb4b6a-0104-d045-0004-59ff00115e32: SQL compilation error:
Table 'RAW.USER_SESSION_CHANNEL' does not exist
[2025-03-27T19:54:26.506+0000] {taskinstance.py:3310} ERROR - Task failed with exception
Traceback (most recent call last):
  File "/home/airflow/.local/lib/python3.12/site-packages/airflow/models/taskinstance.py", line 767, in _execute_task
    result = _execute_callable(context=context, **execute_callable_kwargs)
             ^^^^^^^^^^^^^^^^^^^^^^^^^^^^^^^^^^^^^^^^^^^^^^^^^^^^^^^^^^^^^
  File "/home/airflow/.local/lib/python3.12/site-packages/airflow/models/taskinstance.py", line 733, in _execute_callable
    return ExecutionCallableRunner(
           ^^^^^^^^^^^^^^^^^^^^^^^^
  File "/home/airflow/.local/lib/python3.12/site-packages/airflow/utils/operator_helpers.py", line 252, in run
    return self.func(*args, **kwargs)
           ^^^^^^^^^^^^^^^^^^^^^^^^^^
  File "/home/airflow/.local/lib/python3.12/site-packages/airflow/models/baseoperator.py", line 406, in wrapper
    return func(self, *args, **kwargs)
           ^^^^^^^^^^^^^^^^^^^^^^^^^^^
  File "/home/airflow/.local/lib/python3.12/site-packages/airflow/decorators/base.py", line 266, in execute
    return_value = super().execute(context)
                   ^^^^^^^^^^^^^^^^^^^^^^^^
  File "/home/airflow/.local/lib/python3.12/site-packages/airflow/models/baseoperator.py", line 406, in wrapper
    return func(self, *args, **kwargs)
           ^^^^^^^^^^^^^^^^^^^^^^^^^^^
  File "/home/airflow/.local/lib/python3.12/site-packages/airflow/operators/python.py", line 238, in execute
    return_value = self.execute_callable()
                   ^^^^^^^^^^^^^^^^^^^^^^^
  File "/home/airflow/.local/lib/python3.12/site-packages/airflow/operators/python.py", line 256, in execute_callable
    return runner.run(*self.op_args, **self.op_kwargs)
           ^^^^^^^^^^^^^^^^^^^^^^^^^^^^^^^^^^^^^^^^^^^
  File "/home/airflow/.local/lib/python3.12/site-packages/airflow/utils/operator_helpers.py", line 252, in run
    return self.func(*args, **kwargs)
           ^^^^^^^^^^^^^^^^^^^^^^^^^^
  File "/opt/airflow/dags/import_dag_hw_6.py", line 28, in load_raw_data
    cur.execute(sql_copy_user)
  File "/home/airflow/.local/lib/python3.12/site-packages/snowflake/connector/cursor.py", line 1087, in execute
    Error.errorhandler_wrapper(self.connection, self, error_class, errvalue)
  File "/home/airflow/.local/lib/python3.12/site-packages/snowflake/connector/errors.py", line 284, in errorhandler_wrapper
    handed_over = Error.hand_to_other_handler(
                  ^^^^^^^^^^^^^^^^^^^^^^^^^^^^
  File "/home/airflow/.local/lib/python3.12/site-packages/snowflake/connector/errors.py", line 339, in hand_to_other_handler
    cursor.errorhandler(connection, cursor, error_class, error_value)
  File "/home/airflow/.local/lib/python3.12/site-packages/snowflake/connector/errors.py", line 215, in default_errorhandler
    raise error_class(
snowflake.connector.errors.ProgrammingError: 001757 (42601): 01bb4b6a-0104-d045-0004-59ff00115e32: SQL compilation error:
Table 'RAW.USER_SESSION_CHANNEL' does not exist
[2025-03-27T19:54:26.523+0000] {taskinstance.py:1225} INFO - Marking task as FAILED. dag_id=etl_snowflake, task_id=load_raw_data, run_id=manual__2025-03-27T19:54:23.865818+00:00, execution_date=20250327T195423, start_date=20250327T195425, end_date=20250327T195426
[2025-03-27T19:54:26.546+0000] {taskinstance.py:340} INFO - ::group::Post task execution logs
[2025-03-27T19:54:26.548+0000] {standard_task_runner.py:124} ERROR - Failed to execute job 78 for task load_raw_data (001757 (42601): 01bb4b6a-0104-d045-0004-59ff00115e32: SQL compilation error:
Table 'RAW.USER_SESSION_CHANNEL' does not exist; 658)
Traceback (most recent call last):
  File "/home/airflow/.local/lib/python3.12/site-packages/airflow/task/task_runner/standard_task_runner.py", line 117, in _start_by_fork
    ret = args.func(args, dag=self.dag)
          ^^^^^^^^^^^^^^^^^^^^^^^^^^^^^
  File "/home/airflow/.local/lib/python3.12/site-packages/airflow/cli/cli_config.py", line 49, in command
    return func(*args, **kwargs)
           ^^^^^^^^^^^^^^^^^^^^^
  File "/home/airflow/.local/lib/python3.12/site-packages/airflow/utils/cli.py", line 115, in wrapper
    return f(*args, **kwargs)
           ^^^^^^^^^^^^^^^^^^
  File "/home/airflow/.local/lib/python3.12/site-packages/airflow/cli/commands/task_command.py", line 483, in task_run
    task_return_code = _run_task_by_selected_method(args, _dag, ti)
                       ^^^^^^^^^^^^^^^^^^^^^^^^^^^^^^^^^^^^^^^^^^^^
  File "/home/airflow/.local/lib/python3.12/site-packages/airflow/cli/commands/task_command.py", line 256, in _run_task_by_selected_method
    return _run_raw_task(args, ti)
           ^^^^^^^^^^^^^^^^^^^^^^^
  File "/home/airflow/.local/lib/python3.12/site-packages/airflow/cli/commands/task_command.py", line 341, in _run_raw_task
    return ti._run_raw_task(
           ^^^^^^^^^^^^^^^^^
  File "/home/airflow/.local/lib/python3.12/site-packages/airflow/utils/session.py", line 97, in wrapper
    return func(*args, session=session, **kwargs)
           ^^^^^^^^^^^^^^^^^^^^^^^^^^^^^^^^^^^^^^
  File "/home/airflow/.local/lib/python3.12/site-packages/airflow/models/taskinstance.py", line 3004, in _run_raw_task
    return _run_raw_task(
           ^^^^^^^^^^^^^^
  File "/home/airflow/.local/lib/python3.12/site-packages/airflow/models/taskinstance.py", line 273, in _run_raw_task
    TaskInstance._execute_task_with_callbacks(
  File "/home/airflow/.local/lib/python3.12/site-packages/airflow/models/taskinstance.py", line 3158, in _execute_task_with_callbacks
    result = self._execute_task(context, task_orig)
             ^^^^^^^^^^^^^^^^^^^^^^^^^^^^^^^^^^^^^^
  File "/home/airflow/.local/lib/python3.12/site-packages/airflow/models/taskinstance.py", line 3182, in _execute_task
    return _execute_task(self, context, task_orig)
           ^^^^^^^^^^^^^^^^^^^^^^^^^^^^^^^^^^^^^^^
  File "/home/airflow/.local/lib/python3.12/site-packages/airflow/models/taskinstance.py", line 767, in _execute_task
    result = _execute_callable(context=context, **execute_callable_kwargs)
             ^^^^^^^^^^^^^^^^^^^^^^^^^^^^^^^^^^^^^^^^^^^^^^^^^^^^^^^^^^^^^
  File "/home/airflow/.local/lib/python3.12/site-packages/airflow/models/taskinstance.py", line 733, in _execute_callable
    return ExecutionCallableRunner(
           ^^^^^^^^^^^^^^^^^^^^^^^^
  File "/home/airflow/.local/lib/python3.12/site-packages/airflow/utils/operator_helpers.py", line 252, in run
    return self.func(*args, **kwargs)
           ^^^^^^^^^^^^^^^^^^^^^^^^^^
  File "/home/airflow/.local/lib/python3.12/site-packages/airflow/models/baseoperator.py", line 406, in wrapper
    return func(self, *args, **kwargs)
           ^^^^^^^^^^^^^^^^^^^^^^^^^^^
  File "/home/airflow/.local/lib/python3.12/site-packages/airflow/decorators/base.py", line 266, in execute
    return_value = super().execute(context)
                   ^^^^^^^^^^^^^^^^^^^^^^^^
  File "/home/airflow/.local/lib/python3.12/site-packages/airflow/models/baseoperator.py", line 406, in wrapper
    return func(self, *args, **kwargs)
           ^^^^^^^^^^^^^^^^^^^^^^^^^^^
  File "/home/airflow/.local/lib/python3.12/site-packages/airflow/operators/python.py", line 238, in execute
    return_value = self.execute_callable()
                   ^^^^^^^^^^^^^^^^^^^^^^^
  File "/home/airflow/.local/lib/python3.12/site-packages/airflow/operators/python.py", line 256, in execute_callable
    return runner.run(*self.op_args, **self.op_kwargs)
           ^^^^^^^^^^^^^^^^^^^^^^^^^^^^^^^^^^^^^^^^^^^
  File "/home/airflow/.local/lib/python3.12/site-packages/airflow/utils/operator_helpers.py", line 252, in run
    return self.func(*args, **kwargs)
           ^^^^^^^^^^^^^^^^^^^^^^^^^^
  File "/opt/airflow/dags/import_dag_hw_6.py", line 28, in load_raw_data
    cur.execute(sql_copy_user)
  File "/home/airflow/.local/lib/python3.12/site-packages/snowflake/connector/cursor.py", line 1087, in execute
    Error.errorhandler_wrapper(self.connection, self, error_class, errvalue)
  File "/home/airflow/.local/lib/python3.12/site-packages/snowflake/connector/errors.py", line 284, in errorhandler_wrapper
    handed_over = Error.hand_to_other_handler(
                  ^^^^^^^^^^^^^^^^^^^^^^^^^^^^
  File "/home/airflow/.local/lib/python3.12/site-packages/snowflake/connector/errors.py", line 339, in hand_to_other_handler
    cursor.errorhandler(connection, cursor, error_class, error_value)
  File "/home/airflow/.local/lib/python3.12/site-packages/snowflake/connector/errors.py", line 215, in default_errorhandler
    raise error_class(
snowflake.connector.errors.ProgrammingError: 001757 (42601): 01bb4b6a-0104-d045-0004-59ff00115e32: SQL compilation error:
Table 'RAW.USER_SESSION_CHANNEL' does not exist
[2025-03-27T19:54:26.580+0000] {local_task_job_runner.py:266} INFO - Task exited with return code 1
[2025-03-27T19:54:26.597+0000] {taskinstance.py:3900} INFO - 0 downstream tasks scheduled from follow-on schedule check
[2025-03-27T19:54:26.599+0000] {local_task_job_runner.py:245} INFO - ::endgroup::
